<?xml version="1.0" encoding="utf-8"?><testsuites><testsuite name="pytest" errors="2" failures="0" skipped="0" tests="2" time="2.570" timestamp="2021-09-03T10:50:55.991005" hostname="localhost"><testcase classname="tests.test_messaging" name="test_send_trust_ping" time="1.612"><error message="failed on setup with &quot;pydantic.error_wrappers.ValidationError: 1 validation error for DIDCreate&#10;__root__&#10;  DIDCreate expected dict not NoneType (type=type_error)&quot;">args = (), kwargs = {}, request = &lt;SubRequest 'async_client_bob_module_scope' for &lt;Function test_send_trust_ping&gt;&gt;
setup = &lt;function pytest_fixture_setup.&lt;locals&gt;.wrapper.&lt;locals&gt;.setup at 0x7f7113c6ce50&gt;
finalizer = &lt;function pytest_fixture_setup.&lt;locals&gt;.wrapper.&lt;locals&gt;.finalizer at 0x7f7113c6cee0&gt;

    def wrapper(*args, **kwargs):
        loop = fixture_stripper.get_and_strip_from(
            FixtureStripper.EVENT_LOOP, kwargs
        )
        request = fixture_stripper.get_and_strip_from(
            FixtureStripper.REQUEST, kwargs
        )

        gen_obj = generator(*args, **kwargs)

        async def setup():
            res = await gen_obj.__anext__()
            return res

        def finalizer():
            """Yield again, to finalize."""

            async def async_finalizer():
                try:
                    await gen_obj.__anext__()
                except StopAsyncIteration:
                    pass
                else:
                    msg = "Async generator fixture didn't stop."
                    msg += "Yield only once."
                    raise ValueError(msg)

            loop.run_until_complete(async_finalizer())

        request.addfinalizer(finalizer)
&gt;       return loop.run_until_complete(setup())

../.venv-fastapi/lib/python3.8/site-packages/pytest_asyncio/plugin.py:142:
_ _ _ _ _ _ _ _ _ _ _ _ _ _ _ _ _ _ _ _ _ _ _ _ _ _ _ _ _ _ _ _ _ _ _ _ _ _ _ _ _ _ _ _ _ _ _ _ _ _ _ _ _ _ _ _ _ _ _ _ _ _ _ _ _ _ _ _ _ _ _ _ _
/usr/lib/python3.8/asyncio/base_events.py:616: in run_until_complete
    return future.result()
../.venv-fastapi/lib/python3.8/site-packages/pytest_asyncio/plugin.py:123: in setup
    res = await gen_obj.__anext__()
app/tests/conftest.py:99: in async_client_bob_module_scope
    async with agent_client(async_client, "bob") as client:
app/tests/conftest.py:118: in agent_client
    agent = await async_next(create_wallet(async_client, name))
app/tests/test_dependencies.py:77: in async_next
    async for item in param:
app/tests/conftest.py:156: in create_wallet
    await async_client.get(
../.venv-fastapi/lib/python3.8/site-packages/httpx/_client.py:1661: in get
    return await self.request(
../.venv-fastapi/lib/python3.8/site-packages/httpx/_client.py:1425: in request
    response = await self.send(
../.venv-fastapi/lib/python3.8/site-packages/httpx/_client.py:1510: in send
    response = await self._send_handling_auth(
../.venv-fastapi/lib/python3.8/site-packages/httpx/_client.py:1545: in _send_handling_auth
    response = await self._send_handling_redirects(
../.venv-fastapi/lib/python3.8/site-packages/httpx/_client.py:1579: in _send_handling_redirects
    response = await self._send_single_request(request, timeout)
../.venv-fastapi/lib/python3.8/site-packages/httpx/_client.py:1620: in _send_single_request
    ) = await transport.handle_async_request(
../.venv-fastapi/lib/python3.8/site-packages/httpx/_transports/asgi.py:157: in handle_async_request
    await self.app(scope, receive, send)
../.venv-fastapi/lib/python3.8/site-packages/fastapi/applications.py:199: in __call__
    await super().__call__(scope, receive, send)
../.venv-fastapi/lib/python3.8/site-packages/starlette/applications.py:112: in __call__
    await self.middleware_stack(scope, receive, send)
../.venv-fastapi/lib/python3.8/site-packages/starlette/middleware/errors.py:181: in __call__
    raise exc from None
../.venv-fastapi/lib/python3.8/site-packages/starlette/middleware/errors.py:159: in __call__
    await self.app(scope, receive, _send)
../.venv-fastapi/lib/python3.8/site-packages/starlette/exceptions.py:82: in __call__
    raise exc from None
../.venv-fastapi/lib/python3.8/site-packages/starlette/exceptions.py:71: in __call__
    await self.app(scope, receive, sender)
../.venv-fastapi/lib/python3.8/site-packages/starlette/routing.py:580: in __call__
    await route.handle(scope, receive, send)
../.venv-fastapi/lib/python3.8/site-packages/starlette/routing.py:241: in handle
    await self.app(scope, receive, send)
../.venv-fastapi/lib/python3.8/site-packages/starlette/routing.py:52: in app
    response = await func(request)
../.venv-fastapi/lib/python3.8/site-packages/fastapi/routing.py:214: in app
    raw_response = await run_endpoint_function(
../.venv-fastapi/lib/python3.8/site-packages/fastapi/routing.py:149: in run_endpoint_function
    return await dependant.call(**values)
app/generic/wallet/wallets.py:50: in create_local_did
    return await aries_controller.wallet.create_did()
../.venv-fastapi/lib/python3.8/site-packages/aries_cloudcontroller/api/wallet.py:29: in create_did
    return await self.__create_did(
../.venv-fastapi/lib/python3.8/site-packages/uplink/builder.py:95: in __call__
    self._request_definition.define_request(request_builder, args, kwargs)
../.venv-fastapi/lib/python3.8/site-packages/uplink/commands.py:284: in define_request
    self._argument_handler.handle_call(
../.venv-fastapi/lib/python3.8/site-packages/uplink/arguments.py:154: in handle_call
    self.handle_call_args(request_builder, call_args)
../.venv-fastapi/lib/python3.8/site-packages/uplink/arguments.py:159: in handle_call_args
    annotation.modify_request(request_builder, call_args[name])
../.venv-fastapi/lib/python3.8/site-packages/uplink/arguments.py:183: in modify_request
    converted_value = converter(value) if converter else value
../.venv-fastapi/lib/python3.8/site-packages/uplink/converters/interfaces.py:6: in __call__
    return self.convert(*args, **kwargs)
../.venv-fastapi/lib/python3.8/site-packages/aries_cloudcontroller/util/pydantic_converter.py:56: in convert
    return _encode_pydantic(self._model.parse_obj(value))
_ _ _ _ _ _ _ _ _ _ _ _ _ _ _ _ _ _ _ _ _ _ _ _ _ _ _ _ _ _ _ _ _ _ _ _ _ _ _ _ _ _ _ _ _ _ _ _ _ _ _ _ _ _ _ _ _ _ _ _ _ _ _ _ _ _ _ _ _ _ _ _ _

&gt;   ???
E   pydantic.error_wrappers.ValidationError: 1 validation error for DIDCreate
E   __root__
E     DIDCreate expected dict not NoneType (type=type_error)

pydantic/main.py:577: ValidationError</error></testcase><testcase classname="tests.test_messaging" name="test_send_message" time="0.004"><error message="failed on setup with &quot;pydantic.error_wrappers.ValidationError: 1 validation error for DIDCreate&#10;__root__&#10;  DIDCreate expected dict not NoneType (type=type_error)&quot;">args = (), kwargs = {}, request = &lt;SubRequest 'async_client_bob_module_scope' for &lt;Function test_send_trust_ping&gt;&gt;
setup = &lt;function pytest_fixture_setup.&lt;locals&gt;.wrapper.&lt;locals&gt;.setup at 0x7f7113c6ce50&gt;
finalizer = &lt;function pytest_fixture_setup.&lt;locals&gt;.wrapper.&lt;locals&gt;.finalizer at 0x7f7113c6cee0&gt;

    def wrapper(*args, **kwargs):
        loop = fixture_stripper.get_and_strip_from(
            FixtureStripper.EVENT_LOOP, kwargs
        )
        request = fixture_stripper.get_and_strip_from(
            FixtureStripper.REQUEST, kwargs
        )

        gen_obj = generator(*args, **kwargs)

        async def setup():
            res = await gen_obj.__anext__()
            return res

        def finalizer():
            """Yield again, to finalize."""

            async def async_finalizer():
                try:
                    await gen_obj.__anext__()
                except StopAsyncIteration:
                    pass
                else:
                    msg = "Async generator fixture didn't stop."
                    msg += "Yield only once."
                    raise ValueError(msg)

            loop.run_until_complete(async_finalizer())

        request.addfinalizer(finalizer)
&gt;       return loop.run_until_complete(setup())

../.venv-fastapi/lib/python3.8/site-packages/pytest_asyncio/plugin.py:142:
_ _ _ _ _ _ _ _ _ _ _ _ _ _ _ _ _ _ _ _ _ _ _ _ _ _ _ _ _ _ _ _ _ _ _ _ _ _ _ _ _ _ _ _ _ _ _ _ _ _ _ _ _ _ _ _ _ _ _ _ _ _ _ _ _ _ _ _ _ _ _ _ _
/usr/lib/python3.8/asyncio/base_events.py:616: in run_until_complete
    return future.result()
../.venv-fastapi/lib/python3.8/site-packages/pytest_asyncio/plugin.py:123: in setup
    res = await gen_obj.__anext__()
app/tests/conftest.py:99: in async_client_bob_module_scope
    async with agent_client(async_client, "bob") as client:
app/tests/conftest.py:118: in agent_client
    agent = await async_next(create_wallet(async_client, name))
app/tests/test_dependencies.py:77: in async_next
    async for item in param:
app/tests/conftest.py:156: in create_wallet
    await async_client.get(
../.venv-fastapi/lib/python3.8/site-packages/httpx/_client.py:1661: in get
    return await self.request(
../.venv-fastapi/lib/python3.8/site-packages/httpx/_client.py:1425: in request
    response = await self.send(
../.venv-fastapi/lib/python3.8/site-packages/httpx/_client.py:1510: in send
    response = await self._send_handling_auth(
../.venv-fastapi/lib/python3.8/site-packages/httpx/_client.py:1545: in _send_handling_auth
    response = await self._send_handling_redirects(
../.venv-fastapi/lib/python3.8/site-packages/httpx/_client.py:1579: in _send_handling_redirects
    response = await self._send_single_request(request, timeout)
../.venv-fastapi/lib/python3.8/site-packages/httpx/_client.py:1620: in _send_single_request
    ) = await transport.handle_async_request(
../.venv-fastapi/lib/python3.8/site-packages/httpx/_transports/asgi.py:157: in handle_async_request
    await self.app(scope, receive, send)
../.venv-fastapi/lib/python3.8/site-packages/fastapi/applications.py:199: in __call__
    await super().__call__(scope, receive, send)
../.venv-fastapi/lib/python3.8/site-packages/starlette/applications.py:112: in __call__
    await self.middleware_stack(scope, receive, send)
../.venv-fastapi/lib/python3.8/site-packages/starlette/middleware/errors.py:181: in __call__
    raise exc from None
../.venv-fastapi/lib/python3.8/site-packages/starlette/middleware/errors.py:159: in __call__
    await self.app(scope, receive, _send)
../.venv-fastapi/lib/python3.8/site-packages/starlette/exceptions.py:82: in __call__
    raise exc from None
../.venv-fastapi/lib/python3.8/site-packages/starlette/exceptions.py:71: in __call__
    await self.app(scope, receive, sender)
../.venv-fastapi/lib/python3.8/site-packages/starlette/routing.py:580: in __call__
    await route.handle(scope, receive, send)
../.venv-fastapi/lib/python3.8/site-packages/starlette/routing.py:241: in handle
    await self.app(scope, receive, send)
../.venv-fastapi/lib/python3.8/site-packages/starlette/routing.py:52: in app
    response = await func(request)
../.venv-fastapi/lib/python3.8/site-packages/fastapi/routing.py:214: in app
    raw_response = await run_endpoint_function(
../.venv-fastapi/lib/python3.8/site-packages/fastapi/routing.py:149: in run_endpoint_function
    return await dependant.call(**values)
app/generic/wallet/wallets.py:50: in create_local_did
    return await aries_controller.wallet.create_did()
../.venv-fastapi/lib/python3.8/site-packages/aries_cloudcontroller/api/wallet.py:29: in create_did
    return await self.__create_did(
../.venv-fastapi/lib/python3.8/site-packages/uplink/builder.py:95: in __call__
    self._request_definition.define_request(request_builder, args, kwargs)
../.venv-fastapi/lib/python3.8/site-packages/uplink/commands.py:284: in define_request
    self._argument_handler.handle_call(
../.venv-fastapi/lib/python3.8/site-packages/uplink/arguments.py:154: in handle_call
    self.handle_call_args(request_builder, call_args)
../.venv-fastapi/lib/python3.8/site-packages/uplink/arguments.py:159: in handle_call_args
    annotation.modify_request(request_builder, call_args[name])
../.venv-fastapi/lib/python3.8/site-packages/uplink/arguments.py:183: in modify_request
    converted_value = converter(value) if converter else value
../.venv-fastapi/lib/python3.8/site-packages/uplink/converters/interfaces.py:6: in __call__
    return self.convert(*args, **kwargs)
../.venv-fastapi/lib/python3.8/site-packages/aries_cloudcontroller/util/pydantic_converter.py:56: in convert
    return _encode_pydantic(self._model.parse_obj(value))
_ _ _ _ _ _ _ _ _ _ _ _ _ _ _ _ _ _ _ _ _ _ _ _ _ _ _ _ _ _ _ _ _ _ _ _ _ _ _ _ _ _ _ _ _ _ _ _ _ _ _ _ _ _ _ _ _ _ _ _ _ _ _ _ _ _ _ _ _ _ _ _ _

&gt;   ???
E   pydantic.error_wrappers.ValidationError: 1 validation error for DIDCreate
E   __root__
E     DIDCreate expected dict not NoneType (type=type_error)

pydantic/main.py:577: ValidationError</error></testcase></testsuite></testsuites>